Workbook

Sheet Customers
A1: Customer ID | B1: C_Name | C1: C_phone | D1: Vehi_Num | E1: Vehi_brand | F1: Vehi_name | G1: Address | H1: F_Visit_Date | I1: L_Service_Date | J1: Next_Service | K1: Note
A2: {=IF(LEN(B2:B10520), "CUST"&TEXT(ROW(B2:B10520)-1,"0000"), "")} -> CUST0001 | B2: HARSHADBHAI VAGHELA | C2: 9898284327 | D2: GJ27CN9504 | E2: HEROPESSIONPROBLACK | F2: HEROPESSIONPRO | G2: GATRAD GAM | H2: 25/03/2023 | I2: 45010 | J2: =IF(I2="","",EDATE(I2,3)) -> 45102
A3: CUST0002 | B3: JASHWANT PRAJAPATI | C3: 9824820017 | D3: GJ27BJ9478 | E3: HONDASHINEBLACK | F3: HONDASHINE | H3: 27/05/2020 | I3: 43978 | J3: =IF(I3="","",EDATE(I3,3)) -> 44070
A4: CUST0003 | B4: NARESHBHAI PATEL | C4: 9924748010 | D4: GJ27E4534 | E4: ACTIVA BLACK | F4: ACTIVA | H4: 21/11/2022 | I4: 44886 | J4: =IF(I4="","",EDATE(I4,3)) -> 44978
A5: CUST0004 | B5: YOGESH MAHESHBHAI GAJJAR | C5: 9601065325 | D5: GJ27Q1004 | E5: ACTIVA BLACK | F5: ACTIVA | G5: B-85 NIGAM SOCIETY | H5: 30/11/2019 | I5: 43799 | J5: =IF(I5="","",EDATE(I5,3)) -> 43890
A6: CUST0005 | B6: UPENDRABHAI PATEL | C6: 9974591740 | D6: GJ01SB0672 | E6: MAHINDRACENTURIOBLAC | F6: MAHINDRACENTURIO | G6: B-1/41 AALOK - 5, | H6: 29/11/2022 | I6: 44894 | J6: =IF(I6="","",EDATE(I6,3)) -> 44985
A7: CUST0006 | B7: DHAVALBHAI | C7: 9726937785 | D7: GJ27BR2787 | E7: HEROPESSIONPROBLACK | F7: HEROPESSIONPRO | G7: AVDH RE | H7: 29/11/2019 | I7: 43798 | J7: =IF(I7="","",EDATE(I7,3)) -> 43890
A8: CUST0007 | B8: PRAKASHBHAI THAKOR | C8: 9824540194 | D8: GJ27J7699 | E8: DREEM YUGA | F8: HONDA | H8: 21/05/2023 | I8: 45067 | J8: =IF(I8="","",EDATE(I8,3)) -> 45159
A9: CUST0008 | B9: KIRAN BHAI PATEL | C9: 9924691071 | D9: GJ02BL5262 | E9: DREEM YUGA | F9: HONDA | G9: B102 KENSHASH | H9: 29/11/2019 | I9: 43798 | J9: =IF(I9="","",EDATE(I9,3)) -> 43890
A10: CUST0009 | B10: ANKIT PATEL | C10: 9737548662 | D10: GJ01JN6237 | E10: ACTIVA BLACK | F10: ACTIVA | H10: 28/10/2023 | I10: 45227 | J10: =IF(I10="","",EDATE(I10,3)) -> 45319
A11: CUST0010 | B11: DHARMIK BHARATBHAI PATEL | C11: 7777981411 | D11: GJ27BK9776 | E11: ACTIVABLACK | F11: ACTIVA 4G | G11: N501, UTSAV CITY | H11: 14/04/2023 | I11: 45030 | J11: =IF(I11="","",EDATE(I11,3)) -> 45121
A12: CUST0011 | B12: KEVALBHAI KIRITBHAI PATEL | C12: 9979124383 | D12: GJ27BG3046 | E12: ACTIVA | F12: ACTIVA 3G | G12: A-2 402,SHASHVAT-3 | H12: 45937 | I12: 45848 | J12: =IF(I12="","",EDATE(I12,3)) -> 45940
A13: CUST0012 | B13: NIKUBHAI PATEL | C13: 9099036478 | D13: GJ7BG5464 | E13: ACTIVA | F13: ACTIVA 3G | H13: 43508 | I13: 43801 | J13: =IF(I13="","",EDATE(I13,3)) -> 43892
A14: CUST0013 | B14: KISHANBHAI PATEL | C14: 9725812836 | D14: GJ27AF3505 | E14: SPLENDOR PLUS | F14: SPLENDOR PLUS | G14: F 301 AVADH RES | H14: 22/03/2023 | I14: 45007 | J14: =IF(I14="","",EDATE(I14,3)) -> 45099
A15: CUST0014 | B15: VIJAYBHAI PATEL | C15: 8153914181 | D15: GJ27BG5156 | E15: SHINE | F15: CB SHINE | G15: A 2/104 AKSHARDHAM RES | H15: 22/07/2025 | I15: 45860 | J15: =IF(I15="","",EDATE(I15,3)) -> 45952
A16: CUST0015 | B16: JAYKUMAR SANTIBHAI PRAJAPATI | C16: 9909773168 | D16: GJ24AE3372 | E16: DREEM YUGA | F16: HONDA | G16: RATANPURA GAM | H16: 43477 | I16: 43800 | J16: =IF(I16="","",EDATE(I16,3)) -> 43891
A17: CUST0016 | B17: JAY MAKWANA | C17: 8487811424 | D17: GJ27CD2995 | E17: HONDASHINEBLACK | F17: HONDASHINE | G17: BAPUNAGAR | H17: 21/08/2022 | I17: 44794 | J17: =IF(I17="","",EDATE(I17,3)) -> 44886
A18: CUST0017 | B18: CHANDRESHBHAI PATEL | C18: 9722265074 | D18: GJ27F1767 | E18: SPLENDOR PLUS | F18: SPLENDOR PLUS | G18: 65 AKSHARDHAM SOC | H18: - - | I18: 46012 | J18: =IF(I18="","",EDATE(I18,3)) -> 46102
A19: CUST0018 | B19: BHAVESH BHAI B PATEL | C19: 8140204097 | D19: GJ27BJ7884 | E19: PASSION PRO | F19: PASSION PRO | G19: D7 SWAMINARAYAN PARK | H19: 23/08/2020 | I19: 44066 | J19: =IF(I19="","",EDATE(I19,3)) -> 44158
A20: CUST0019 | B20: JAIMINBHAI PATEL | C20: 8780099699 | D20: GJ38C6212 | E20: SUZUKIGIXXER | F20: SUZUKIGIXXER | G20: L 404,USHAV CITY | H20: 46268 | I20: 46090 | J20: =IF(I20="","",EDATE(I20,3)) -> 46182
A21: CUST0020 | B21: SAKATI B GOHIL | C21: 9924503311 | D21: GJ27CK9688 | E21: PASSION PRO | F21: PASSION PRO | G21: A/83,SWAPNA SHRUSHTI SOC | H21: 45788 | I21: 45966 | J21: =IF(I21="","",EDATE(I21,3)) -> 46058
A22: CUST0021 | B22: SHILESH BHAI PANCHAL | C22: 9723335148 | D22: GJ01NM7895 | E22: PASSION PRO | F22: PASSION PRO | G22: Z,202 DEVNANDANSUPREM | H22: 44441 | I22: 44236 | J22: =IF(I22="","",EDATE(I22,3)) -> 44325
A23: CUST0022 | B23: KARTIK BHAI PATEL | C23: 9712932383 | D23: GJ27AG1367 | E23: ACTIVA WHITE | F23: ACTIVA | G23: PART1,J-101 KRISH AVENU | H23: - - | I23: 46012 | J23: =IF(I23="","",EDATE(I23,3)) -> 46102
A24: CUST0023 | B24: ALKESHBHAI DESAI | C24: 9824324807 | D24: GJ27BK6713 | E24: ACTIVA | F24: ACTIVA 3G | G24: 17 SHIVSANTI TENAMENT | H24: 44965 | I24: 45140 | J24: =IF(I24="","",EDATE(I24,3)) -> 45232
A25: CUST0024 | B25: CHINTAN BHAI PATRL | C25: 9601500509 | D25: GJ02BC5057 | E25: HEROXTREMBACK | F25: XTREME | G25: F-301 ALOK PERADE 1 | H25: - - | I25: 46012 | J25: =IF(I25="","",EDATE(I25,3)) -> 46102
A26: CUST0025 | B26: RKTGERJKER | C26: 3336464646 | D26: GJ1FR2971 | E26: PASSION PRO | F26: PASSION PRO | G26: RENKGNREREJKL | H26: - - | I26: 46012 | J26: =IF(I26="","",EDATE(I26,3)) -> 46102
A27: CUST0026 | B27: PARKASHBHAI THAKOR | C27: 9824540194 | D27: GJ02S7699 | E27: SPLENDOR PLUS | F27: SPLENDOR PLUS | G27: A-101 OMKAR RE, | H27: 31/08/2023 | I27: 45169 | J27: =IF(I27="","",EDATE(I27,3)) -> 45260
A28: CUST0027 | B28: HITESHBHAI | C28: 9427803151 | D28: GJ27AS3151 | E28: HUNK | F28: HUNK HERO | G28: SARNM RE | H28: 45874 | I28: 45785 | J28: =IF(I28="","",EDATE(I28,3)) -> 45877
A29: CUST0028 | B29: HIREN DESHI | C29: 7016991625 | D29: GJ27J5558 | E29: SPLENDOR PLUS | F29: SPLENDOR PLUS | G29: 01,CHITRKUT SOC | H29: 18/06/2020 | I29: 44000 | J29: =IF(I29="","",EDATE(I29,3)) -> 44092
A30: CUST0029 | B30: DHASHARATBHAI | C30: 9825913978 | D30: GJO1FB3346 | E30: SPLENDOR PLUS | F30: SPLENDOR PLUS | G30: 46 SHIVALAY SOC, | H30: - - | I30: 46012 | J30: =IF(I30="","",EDATE(I30,3)) -> 46102
A31: CUST0030 | B31: MUKESH BHAI GUPTA | C31: 8141866900 | D31: GJ27AK8333 | E31: BLACK | F31: TVSAPACHE160 | G31: H-201 SHREE SAREN FLAT | H31: 45575 | I31: 45575 | J31: =IF(I31="","",EDATE(I31,3)) -> 45667
A32: CUST0031 | B32: ANILBHAI DAVE | C32: 7383268947 | D32: GJ27BH6547 | E32: JUPITER BKACK | F32: JUPITER | G32: S-702 SUREYAM ELIGRANC | H32: 26/12/2025 | I32: 46017 | J32: =IF(I32="","",EDATE(I32,3)) -> 46107
A33: CUST0032 | B33: RAKESHBHAI SONI | C33: 9913545226 | D33: GJ01JL8209 | E33: PASSIN PLUS | F33: PASSIN PLUS | G33: M-303 MADHAV HOMES | H33: 43567 | I33: 43803 | J33: =IF(I33="","",EDATE(I33,3)) -> 43894
A34: CUST0033 | B34: CHIRAGBHAI PATEL. | C34: 9558555412 | D34: GJ01LV1773 | E34: AVENGER 150 | F34: AVENGER 150 STREET | G34: 23,KARNAVATI RO HAHUS | H34: 26/11/2021 | I34: 44526 | J34: =IF(I34="","",EDATE(I34,3)) -> 44618
A35: CUST0034 | B35: DIPAK BHAI MEVADA | C35: 8140461426 | D35: GJ084125 | E35: ACCESS125 OLD | F35: ACCESS125 | G35: G 406 SASHVAT MHADEV PART 2 | H35: 43567 | I35: 43803 | J35: =IF(I35="","",EDATE(I35,3)) -> 43894
A36: CUST0035 | B36: DIPAKBHAI MEVADA | C36: 8140461426 | D36: GJ08AF4125 | E36: ACCESS125 OLD | F36: ACCESS125 | G36: G-406,SASHVAT MHADEV PART-2 | H36: 28/02/2024 | I36: 45350 | J36: =IF(I36="","",EDATE(I36,3)) -> 45440
A37: CUST0036 | B37: CHATURBHAI M PATEL | C37: 9558901139 | D37: GJ27BC0611 | E37: ACTIVA | F37: ACTIVA 3G | G37: D-403,KALPTARU HOME | H37: 44748 | I37: 44719 | J37: =IF(I37="","",EDATE(I37,3)) -> 44811
A38: CUST0037 | B38: JAY M KACNALIYA | C38: 9574883489 | D38: GJ27AL8884 | E38: DREEM YUGA | F38: HONDA | G38: B-606,MANSHROVER HI | H38: 43567 | I38: 43803 | J38: =IF(I38="","",EDATE(I38,3)) -> 43894
A39: CUST0038 | B39: BHAVESHBHAI LIMBACHIYA | C39: 9727605815 | D39: GJ02CH3185 | E39: AVENGER 150 | F39: AVENGER 150 STREET | G39: - | H39: - - | I39: 46012 | J39: =IF(I39="","",EDATE(I39,3)) -> 46102
A40: CUST0039 | B40: LALABHAI | C40: 9924081331 | D40: GJ27BF7027 | E40: BAJAJ V-150 | F40: V-150 | G40: B-174 UMIYA NAGAR,ARBUDA NAGAR | H40: 44298 | I40: 44534 | J40: =IF(I40="","",EDATE(I40,3)) -> 44624
...

Sheet customer
A1: Name | B1: phone | C1: Vehicle | D1: plate_number
A2: HARSHADBHAI VAGHELA | B2: 9898284327 | C2: HEROPESSIONPROBLACK | D2: GJ27CN9504
A3: JASHWANT PRAJAPATI | B3: 9824820017 | C3: HONDASHINEBLACK | D3: GJ27BJ9478
A4: NARESHBHAI PATEL | B4: 9924748010 | C4: ACTIVA BLACK | D4: GJ27E4534
A5: YOGESH MAHESHBHAI GAJJAR | B5: 9601065325 | C5: ACTIVA BLACK | D5: GJ27Q1004
A6: UPENDRABHAI PATEL | B6: 9974591740 | C6: MAHINDRACENTURIOBLAC | D6: GJ01SB0672
A7: DHAVALBHAI | B7: 9726937785 | C7: HEROPESSIONPROBLACK | D7: GJ27BR2787
A8: PRAKASHBHAI THAKOR | B8: 9824540194 | C8: DREEM YUGA | D8: GJ27J7699
A9: KIRAN BHAI PATEL | B9: 9924691071 | C9: DREEM YUGA | D9: GJ02BL5262
A10: ANKIT PATEL | B10: 9737548662 | C10: ACTIVA BLACK | D10: GJ01JN6237
A11: DHARMIK BHARATBHAI PATEL | B11: 7777981411 | C11: ACTIVABLACK | D11: GJ27BK9776
A12: KEVALBHAI KIRITBHAI PATEL | B12: 9979124383 | C12: ACTIVA | D12: GJ27BG3046
A13: NIKUBHAI PATEL | B13: 9099036478 | C13: ACTIVA | D13: GJ7BG5464
... A428: PRIYANK R KARPITYA | B428: 9737631780 | C428: PASSION XPRO | D428: GJ27CL3832
A429: RAHULBHAI NARESHBHAI SAMKUNIYA | C429: ACCESS125 OLD | D429: GJ01SD2657
A430: DESAI HARGOVANDBHAI BAMJI | B430: 9998786665 | C430: ES | D430: GJ24AC0237
A431: NAGINBHAI SOLANKI | B431: 9714386220 | C431: PASSION PRO | D431: GJ07CQ7214
A432: HIRALALA GOKULRAM CHAUDRI | B432: 9825778422 | C432: ACTIVA BLACK | D432: GJ27P9484
A433: YOGESHBHAI DINESHBHAI SHARMA | B433: 9925045283 | C433: HONDASHINEBLACK | D433: GJ01FU2966
A434: JITENDRABHAI P TRIVEDI | B434: 9376947022 | C434: TVS WEGO WHITE | D434: GJ05GL5355
A435: JITENDRABHAI P TRIVEDI. | B435: 9376947022 | C435: PASSION PRO | D435: GJ05FC1188
A436: SHILPABEN HARSHADBHAI PANCHAL | B436: 9426037332 | C436: JUPITER BKACK | D436: GJ27CJ6478
A437: PRAVINBHAI D CHAUHAN | B437: 9925505689 | C437: SHINE | D437: GJ27CK0651
A438: JITESHBHAI PRATABBHAI ZALA | B438: 6352764698 | C438: SPLENDOR PLUS | D438: GJ27CA9250
A439: HARGOVAND K DESAI | B439: 9998786665 | C439: ACTIVA BLACK | D439: GJ01JQ1218
A440: NITINBHAI J PATEL | B440: 9924407746 | C440: ACTIVA BLACK | D440: GJ27BK6184
A441: ASHVINBHAI GANGARAMBHAI PATEL | B441: 9825014281 | C441: MESTERO BLACK | D441: GJ27AG560
... A580: VANITABEN PATEL | B580: 9998994713 | C580: JUPITER BKACK | D580: GJ27AQ0674
A581: MIT H PATEL | C581: PASSION PRO | D581: GJ27A51798
A582: BHARATBHAI R PARMAR | B582: 7874911351 | C582: ACTIVA BLACK | D582: GJ01SB4703
A583: NIRAJBHAI YADAV | B583: 9722821056 | C583: PASSION PRO | D583: GJ27F5685
A584: HARDIKBHAI B PATEL | B584: 7016952030 | C584: SPLENDOR PLUS | D584: GJ27AN9937
A585: JAYMINBHAI J PATEL | B585: 7600914791 | C585: SPLENDOR PLUS | D585: GJ01FR0881
A586: MEHULBHAI S JAIN | B586: 9726442111 | C586: ACTIVABLACK | D586: GJ27C7048
A587: JAYKUMAR PATEL | B587: 7878343538 | C587: DREEM YUGA | D587: GJ27S1405
A588: HARDEVSINH VAGHELA | B588: 9724766607 | C588: PASSION PRO | D588: GJ27BP5071
A589: DILIPBHAI PATEL | B589: 9426753128 | C589: SPLENDOR PLUS | D589: GJ24IT4597
A590: DHARMESHBHAI PATEL | B590: 9979534182 | C590: BLACK | D590: GJ27BH9670
A591: BHAVESHBHAI M PATEL | B591: 9537667785 | C591: HF DELUX BLACK | D591: GJ01SH5221
A592: DHRUVBHAI B PATEL | B592: 8155856422 | C592: ACTIVA BLACK | D592: GJ27AD2402
...

Sheet Bookings
A1: Booking ID | B1: Customer ID | C1: C_Name | D1: C_phone | E1: Vehi_Num | F1: Booking Date | G1: Service Date | H1: Status
A2: =IF(B2="","", "BOOK"&TEXT(ROW()-1,"0000")) -> BOOK0001 | B2: CUST0001 | C2: =IFERROR(VLOOKUP(B2,Customers!A:D,2,FALSE),"") -> HARSHADBHAI VAGHELA | D2: =IFERROR(VLOOKUP(B2,Customers!A:D,3,FALSE),"") -> 9898284327 | E2: =IFERROR(VLOOKUP(B2,Customers!A:D,4,FALSE),"") -> GJ27CN9504 | F2: =IF(B2="","",TODAY()) -> 46182 | H2: Completed
A3: =IF(B3="","", "BOOK"&TEXT(ROW()-1,"0000")) -> BOOK0002 | B3: CUST0010 | C3: =IFERROR(VLOOKUP(B3,Customers!A:D,2,FALSE),"") -> DHARMIK BHARATBHAI PATEL | D3: =IFERROR(VLOOKUP(B3,Customers!A:D,3,FALSE),"") -> 7777981411 | E3: =IFERROR(VLOOKUP(B3,Customers!A:D,4,FALSE),"") -> GJ27BK9776 | F3: =IF(B3="","",TODAY()) -> 46182
A4: =IF(B4="","", "BOOK"&TEXT(ROW()-1,"0000")) -> BOOK0003 | B4: CUST0529 | C4: =IFERROR(VLOOKUP(B4,Customers!A:D,2,FALSE),"") -> ROHITBHAI R PATEL | D4: =IFERROR(VLOOKUP(B4,Customers!A:D,3,FALSE),"") -> 6355973218 | E4: =IFERROR(VLOOKUP(B4,Customers!A:D,4,FALSE),"") -> GJ08BJ8846 | F4: =IF(B4="","",TODAY()) -> 46182
A5: =IF(B5="","", "BOOK"&TEXT(ROW()-1,"0000")) | C5: =IFERROR(VLOOKUP(B5,Customers!A:D,2,FALSE),"") | D5: =IFERROR(VLOOKUP(B5,Customers!A:D,3,FALSE),"") | E5: =IFERROR(VLOOKUP(B5,Customers!A:D,4,FALSE),"") | F5: =IF(B5="","",TODAY())
A6: =IF(B6="","", "BOOK"&TEXT(ROW()-1,"0000")) | C6: =IFERROR(VLOOKUP(B6,Customers!A:D,2,FALSE),"") | D6: =IFERROR(VLOOKUP(B6,Customers!A:D,3,FALSE),"") | E6: =IFERROR(VLOOKUP(B6,Customers!A:D,4,FALSE),"") | F6: =IF(B6="","",TODAY())
A7: =IF(B7="","", "BOOK"&TEXT(ROW()-1,"0000")) | C7: =IFERROR(VLOOKUP(B7,Customers!A:D,2,FALSE),"") | D7: =IFERROR(VLOOKUP(B7,Customers!A:D,3,FALSE),"") | E7: =IFERROR(VLOOKUP(B7,Customers!A:D,4,FALSE),"") | F7: =IF(B7="","",TODAY())
A8: =IF(B8="","", "BOOK"&TEXT(ROW()-1,"0000")) | C8: =IFERROR(VLOOKUP(B8,Customers!A:D,2,FALSE),"") | D8: =IFERROR(VLOOKUP(B8,Customers!A:D,3,FALSE),"") | E8: =IFERROR(VLOOKUP(B8,Customers!A:D,4,FALSE),"") | F8: =IF(B8="","",TODAY())
A9: =IF(B9="","", "BOOK"&TEXT(ROW()-1,"0000")) | C9: =IFERROR(VLOOKUP(B9,Customers!A:D,2,FALSE),"") | D9: =IFERROR(VLOOKUP(B9,Customers!A:D,3,FALSE),"") | E9: =IFERROR(VLOOKUP(B9,Customers!A:D,4,FALSE),"") | F9: =IF(B9="","",TODAY())
A10: =IF(B10="","", "BOOK"&TEXT(ROW()-1,"0000")) | C10: =IFERROR(VLOOKUP(B10,Customers!A:D,2,FALSE),"") | D10: =IFERROR(VLOOKUP(B10,Customers!A:D,3,FALSE),"") | E10: =IFERROR(VLOOKUP(B10,Customers!A:D,4,FALSE),"") | F10: =IF(B10="","",TODAY())
A11: =IF(B11="","", "BOOK"&TEXT(ROW()-1,"0000")) | C11: =IFERROR(VLOOKUP(B11,Customers!A:D,2,FALSE),"") | D11: =IFERROR(VLOOKUP(B11,Customers!A:D,3,FALSE),"") | E11: =IFERROR(VLOOKUP(B11,Customers!A:D,4,FALSE),"") | F11: =IF(B11="","",TODAY())
A12: =IF(B12="","", "BOOK"&TEXT(ROW()-1,"0000")) | C12: =IFERROR(VLOOKUP(B12,Customers!A:D,2,FALSE),"") | D12: =IFERROR(VLOOKUP(B12,Customers!A:D,3,FALSE),"") | E12: =IFERROR(VLOOKUP(B12,Customers!A:D,4,FALSE),"") | F12: =IF(B12="","",TODAY())
A13: =IF(B13="","", "BOOK"&TEXT(ROW()-1,"0000")) | C13: =IFERROR(VLOOKUP(B13,Customers!A:D,2,FALSE),"") | D13: =IFERROR(VLOOKUP(B13,Customers!A:D,3,FALSE),"") | E13: =IFERROR(VLOOKUP(B13,Customers!A:D,4,FALSE),"") | F13: =IF(B13="","",TODAY())
A14: =IF(B14="","", "BOOK"&TEXT(ROW()-1,"0000")) | C14: =IFERROR(VLOOKUP(B14,Customers!A:D,2,FALSE),"") | D14: =IFERROR(VLOOKUP(B14,Customers!A:D,3,FALSE),"") | E14: =IFERROR(VLOOKUP(B14,Customers!A:D,4,FALSE),"") | F14: =IF(B14="","",TODAY())
A15: =IF(B15="","", "BOOK"&TEXT(ROW()-1,"0000")) | C15: =IFERROR(VLOOKUP(B15,Customers!A:D,2,FALSE),"") | D15: =IFERROR(VLOOKUP(B15,Customers!A:D,3,FALSE),"") | E15: =IFERROR(VLOOKUP(B15,Customers!A:D,4,FALSE),"") | F15: =IF(B15="","",TODAY())
A16: =IF(B16="","", "BOOK"&TEXT(ROW()-1,"0000")) | C16: =IFERROR(VLOOKUP(B16,Customers!A:D,2,FALSE),"") | D16: =IFERROR(VLOOKUP(B16,Customers!A:D,3,FALSE),"") | E16: =IFERROR(VLOOKUP(B16,Customers!A:D,4,FALSE),"") | F16: =IF(B16="","",TODAY())
... A248: =IF(B248="","", "BOOK"&TEXT(ROW()-1,"0000")) | C248: =IFERROR(VLOOKUP(B248,Customers!A:D,2,FALSE),"") | D248: =IFERROR(VLOOKUP(B248,Customers!A:D,3,FALSE),"") | E248: =IFERROR(VLOOKUP(B248,Customers!A:D,4,FALSE),"") | F248: =IF(B248="","",TODAY())
A249: =IF(B249="","", "BOOK"&TEXT(ROW()-1,"0000"))
A250: =IF(B250="","", "BOOK"&TEXT(ROW()-1,"0000"))
A251: =IF(B251="","", "BOOK"&TEXT(ROW()-1,"0000"))
A252: =IF(B252="","", "BOOK"&TEXT(ROW()-1,"0000"))
A253: =IF(B253="","", "BOOK"&TEXT(ROW()-1,"0000"))
A254: =IF(B254="","", "BOOK"&TEXT(ROW()-1,"0000"))
A255: =IF(B255="","", "BOOK"&TEXT(ROW()-1,"0000"))
A256: =IF(B256="","", "BOOK"&TEXT(ROW()-1,"0000"))
A257: =IF(B257="","", "BOOK"&TEXT(ROW()-1,"0000"))
A258: =IF(B258="","", "BOOK"&TEXT(ROW()-1,"0000"))
A259: =IF(B259="","", "BOOK"&TEXT(ROW()-1,"0000"))
A260: =IF(B260="","", "BOOK"&TEXT(ROW()-1,"0000"))
... A510: =IF(B510="","", "BOOK"&TEXT(ROW()-1,"0000"))
